Workbook

Sheet LEIA-ME
A1: Banco de dados · Cadastro & Criativo
A3: Como usar
A4: Cores | B4: Texto azul = digitação manual. Preto = fórmula (não editar). Linha 2 cinza de cada aba = exemplo de formato; os dados reais começam na linha 3.
A5: Fórmulas | B5: As fórmulas cobrem até a linha 1000. Não deixe linhas em branco no meio dos dados.
A7: Abas
A8: clickup_tarefas | B8: Carga inicial das tarefas do ClickUp (data/clickup.json de 13/10/2026). Daqui em diante a rotina diária acrescenta tarefas novas e atualiza as existentes pelo ID, sem duplicar.
A9: clickup_historico | B9: Uma linha a cada mudança de status detectada pela rotina. Serve para medir quanto tempo a tarefa ficou em cada etapa.
A10: plano_90_dias | B10: Plano de 90 dias: uma linha por atividade, com fase, responsável, prazo, status e peso. O percentual do plano é calculado pelo peso.
A11: fornecedores | B11: Cadastro de fornecedores. Os números de catálogo, cadastrados e disponíveis aparecem sozinhos, a partir da posição mais recente.
A12: posicoes_fornecedor | B12: Registro de posições por fornecedor e data: produtos no catálogo, cadastrados no ERP e disponíveis para venda. Preenchido só pelo time de cadastro.
A13: fornecedor_painel | B13: Escolha o fornecedor na célula amarela e veja catálogo, cadastrados, disponíveis, o que falta cadastrar e as coberturas.
A14: vonder_60 | B14: Projeto Vonder 60: posições periódicas de anúncios publicados e no ERP, com a variação entre posições e a meta.
A15: lotes | B15: Lotes de cadastro (planilhas recebidas): datas de recebimento, início e conclusão, e devoluções. Base do tempo médio de execução.
A16: metas_base | B16: Valores de base e metas planejadas de cada indicador. Estão em branco: só preencha o que a gestão aprovou.
A17: relatorios | B17: Planejado × realizado, com fórmulas lendo as demais abas.
A19: Limites conhecidos
A20: Tempo de execução | B20: O ClickUp devolvido pela rotina não traz a data de criação da tarefa. Por isso o tempo médio de execução vem da aba lotes (início → conclusão). Para tarefas do ClickUp, o tempo só será confiável depois que clickup_historico acumular mudanças de status.
A21: Prazo cumprido | B21: Considera só tarefas concluídas que têm prazo. Concluída no dia do prazo conta como no prazo.
A22: Filial | B22: Vem da fonte (Itajaí, Londrina) ou da tag da tarefa. Tarefas sem essa informação ficam sem filial.

Sheet relatorios
A1: Relatórios · planejado × realizado
A2: Base e meta vêm da aba metas_base. Realizado é calculado das demais abas. Sem meta preenchida, o status fica em branco.
A4: Indicador | B4: Valor de base | C4: Meta planejada | D4: Realizado | E4: Status | F4: Como é calculado
A5: =metas_base!A3 -> Cumprimento de prazo | B5: =IF(metas_base!D3="","",metas_base!D3) | C5: =IF(metas_base!E3="","",metas_base!E3) | D5: =IF(SUMPRODUCT((clickup_tarefas!$J$2:$J$5000<>"")*(clickup_tarefas!$H$2:$H$5000<>""))=0,"",SUMPRODUCT((clickup_tarefas!$J$2:$J$5000<>"")*(clickup_tarefas!$H$2:$H$5000<>"")*(clickup_tarefas!$J$2:$J$5000<clickup_tarefas!$H$2:$H$5000+1))/SUMPRODUCT((clickup_tarefas!$J$2:$J$5000<>"")*(clickup_tarefas!$H$2:$H$5000<>""))) -> 0.4516129 | E5: =IF(OR(C5="",D5=""),"",IF(metas_base!C3="Menor",IF(D5<=C5,"Dentro da meta","Fora da meta"),IF(D5>=C5,"Dentro da meta","Fora da meta"))) | F5: Concluídas com prazo, fechadas até o dia do prazo ÷ concluídas com prazo (clickup_tarefas)
A6: =metas_base!A4 -> Retrabalho (lotes devolvidos) | B6: =IF(metas_base!D4="","",metas_base!D4) | C6: =IF(metas_base!E4="","",metas_base!E4) | D6: =IF(COUNTA(lotes!$A$3:$A$1000)=0,"",COUNTIF(lotes!$L$3:$L$1000,"Sim")/COUNTA(lotes!$A$3:$A$1000)) | E6: =IF(OR(C6="",D6=""),"",IF(metas_base!C4="Menor",IF(D6<=C6,"Dentro da meta","Fora da meta"),IF(D6>=C6,"Dentro da meta","Fora da meta"))) | F6: Lotes marcados como devolvidos ÷ lotes registrados (lotes)
A7: =metas_base!A5 -> Devolução na 1ª conferência | B7: =IF(metas_base!D5="","",metas_base!D5) | C7: =IF(metas_base!E5="","",metas_base!E5) | D7: =IF(COUNTA(lotes!$I$3:$I$1000)=0,"",COUNTIF(lotes!$I$3:$I$1000,"Devolvida")/COUNTA(lotes!$I$3:$I$1000)) | E7: =IF(OR(C7="",D7=""),"",IF(metas_base!C5="Menor",IF(D7<=C7,"Dentro da meta","Fora da meta"),IF(D7>=C7,"Dentro da meta","Fora da meta"))) | F7: Lotes com conferência Devolvida ÷ lotes com conferência preenchida (lotes)
A8: =metas_base!A6 -> Tempo médio de execução do cadastro | B8: =IF(metas_base!D6="","",metas_base!D6) | C8: =IF(metas_base!E6="","",metas_base!E6) | D8: =IFERROR(AVERAGE(lotes!$J$3:$J$1000),"") | E8: =IF(OR(C8="",D8=""),"",IF(metas_base!C6="Menor",IF(D8<=C8,"Dentro da meta","Fora da meta"),IF(D8>=C8,"Dentro da meta","Fora da meta"))) | F8: Média de dias entre início do cadastro e conclusão (lotes)
A9: =metas_base!A7 -> Espera entre recebimento e início | B9: =IF(metas_base!D7="","",metas_base!D7) | C9: =IF(metas_base!E7="","",metas_base!E7) | D9: =IFERROR(AVERAGE(lotes!$K$3:$K$1000),"") | E9: =IF(OR(C9="",D9=""),"",IF(metas_base!C7="Menor",IF(D9<=C9,"Dentro da meta","Fora da meta"),IF(D9>=C9,"Dentro da meta","Fora da meta"))) | F9: Média de dias entre recebimento e início do cadastro (lotes)
A10: =metas_base!A8 -> Plano de 90 dias concluído | B10: =IF(metas_base!D8="","",metas_base!D8) | C10: =IF(metas_base!E8="","",metas_base!E8) | D10: =IF(SUM(plano_90_dias!$I$3:$I$1000)=0,"",SUMPRODUCT(plano_90_dias!$I$3:$I$1000,plano_90_dias!$L$3:$L$1000)/SUM(plano_90_dias!$I$3:$I$1000)) | E10: =IF(OR(C10="",D10=""),"",IF(metas_base!C8="Menor",IF(D10<=C10,"Dentro da meta","Fora da meta"),IF(D10>=C10,"Dentro da meta","Fora da meta"))) | F10: Média do % de cada atividade ponderada pelo peso (plano_90_dias). Atividade sem peso não entra
A11: =metas_base!A9 -> Cobertura média de cadastro dos fornecedores | B11: =IF(metas_base!D9="","",metas_base!D9) | C11: =IF(metas_base!E9="","",metas_base!E9) | D11: =IFERROR(AVERAGE(fornecedores!$I$3:$I$200),"") | E11: =IF(OR(C11="",D11=""),"",IF(metas_base!C9="Menor",IF(D11<=C11,"Dentro da meta","Fora da meta"),IF(D11>=C11,"Dentro da meta","Fora da meta"))) | F11: Média de cadastrados ÷ catálogo nos fornecedores com posição (fornecedores)
A12: =metas_base!A10 -> Cobertura média de venda dos fornecedores | B12: =IF(metas_base!D10="","",metas_base!D10) | C12: =IF(metas_base!E10="","",metas_base!E10) | D12: =IFERROR(AVERAGE(fornecedores!$J$3:$J$200),"") | E12: =IF(OR(C12="",D12=""),"",IF(metas_base!C10="Menor",IF(D12<=C12,"Dentro da meta","Fora da meta"),IF(D12>=C12,"Dentro da meta","Fora da meta"))) | F12: Média de disponíveis ÷ catálogo nos fornecedores com posição (fornecedores)
A13: =metas_base!A11 -> Vonder 60: anúncios publicados | B13: =IF(metas_base!D11="","",metas_base!D11) | C13: =IF(metas_base!E11="","",metas_base!E11) | D13: =vonder_60!$H$3 | E13: =IF(OR(C13="",D13=""),"",IF(metas_base!C11="Menor",IF(D13<=C13,"Dentro da meta","Fora da meta"),IF(D13>=C13,"Dentro da meta","Fora da meta"))) | F13: Posição mais recente em vonder_60
A16: Tarefas do ClickUp por fonte
A17: Fonte | B17: Total | C17: Abertas | D17: Concluídas | E17: Atrasadas (abertas com prazo vencido)
A18: anuncios | B18: =COUNTIF(clickup_tarefas!$B$2:$B$5000,A18) -> 1000 | C18: =COUNTIFS(clickup_tarefas!$B$2:$B$5000,A18,clickup_tarefas!$J$2:$J$5000,"") -> 38 | D18: =COUNTIFS(clickup_tarefas!$B$2:$B$5000,A18,clickup_tarefas!$J$2:$J$5000,"<>") -> 962 | E18: =SUMPRODUCT((clickup_tarefas!$B$2:$B$5000=A18)*(clickup_tarefas!$J$2:$J$5000="")*(clickup_tarefas!$H$2:$H$5000<>"")*(clickup_tarefas!$H$2:$H$5000<TODAY())) -> 1
A19: compras | B19: =COUNTIF(clickup_tarefas!$B$2:$B$5000,A19) -> 19 | C19: =COUNTIFS(clickup_tarefas!$B$2:$B$5000,A19,clickup_tarefas!$J$2:$J$5000,"") -> 0 | D19: =COUNTIFS(clickup_tarefas!$B$2:$B$5000,A19,clickup_tarefas!$J$2:$J$5000,"<>") -> 19 | E19: =SUMPRODUCT((clickup_tarefas!$B$2:$B$5000=A19)*(clickup_tarefas!$J$2:$J$5000="")*(clickup_tarefas!$H$2:$H$5000<>"")*(clickup_tarefas!$H$2:$H$5000<TODAY())) -> 0
A20: itajai | B20: =COUNTIF(clickup_tarefas!$B$2:$B$5000,A20) -> 25 | C20: =COUNTIFS(clickup_tarefas!$B$2:$B$5000,A20,clickup_tarefas!$J$2:$J$5000,"") -> 3 | D20: =COUNTIFS(clickup_tarefas!$B$2:$B$5000,A20,clickup_tarefas!$J$2:$J$5000,"<>") -> 22 | E20: =SUMPRODUCT((clickup_tarefas!$B$2:$B$5000=A20)*(clickup_tarefas!$J$2:$J$5000="")*(clickup_tarefas!$H$2:$H$5000<>"")*(clickup_tarefas!$H$2:$H$5000<TODAY())) -> 0
A21: londrina | B21: =COUNTIF(clickup_tarefas!$B$2:$B$5000,A21) -> 45 | C21: =COUNTIFS(clickup_tarefas!$B$2:$B$5000,A21,clickup_tarefas!$J$2:$J$5000,"") -> 26 | D21: =COUNTIFS(clickup_tarefas!$B$2:$B$5000,A21,clickup_tarefas!$J$2:$J$5000,"<>") -> 19 | E21: =SUMPRODUCT((clickup_tarefas!$B$2:$B$5000=A21)*(clickup_tarefas!$J$2:$J$5000="")*(clickup_tarefas!$H$2:$H$5000<>"")*(clickup_tarefas!$H$2:$H$5000<TODAY())) -> 0

Sheet metas_base
A1: Indicador | B1: Unidade | C1: Melhor quando | D1: Valor de base | E1: Meta planejada | F1: Prazo da meta | G1: Fonte da base / observação
A2: Exemplo: Cumprimento de prazo | B2: % | C2: Maior | D2: 0.7 | E2: 0.9 | F2: 46387 | G2: Exemplo: apague esta linha. Percentuais em formato 0,9 = 90%
A3: Cumprimento de prazo | B3: % | C3: Maior
A4: Retrabalho (lotes devolvidos) | B4: % | C4: Menor
A5: Devolução na 1ª conferência | B5: % | C5: Menor
A6: Tempo médio de execução do cadastro | B6: dias | C6: Menor
A7: Espera entre recebimento e início | B7: dias | C7: Menor
A8: Plano de 90 dias concluído | B8: % | C8: Maior
A9: Cobertura média de cadastro dos fornecedores | B9: % | C9: Maior
A10: Cobertura média de venda dos fornecedores | B10: % | C10: Maior
A11: Vonder 60: anúncios publicados | B11: un | C11: Maior

Sheet plano_90_dias
A1: Código | B1: Fase (1 a 3) | C1: Atividade | D1: Responsável | E1: Início | F1: Prazo | G1: Status | H1: % concluído | I1: Peso | J1: Bloqueio | K1: Observações | L1: % considerado | M1: Situação
A2: 1.1 | B2: 1 | C2: Mapear fornecedores prioritários | D2: Polielly Morato | E2: 46314 | F2: 46325 | G2: Em andamento | H2: 0.4 | I2: 2 | K2: Exemplo: apague esta linha | L2: =IF(C2="","",IF(G2="Concluída",1,N(H2))) -> 0.4 | M2: =IF(C2="","",IF(G2="Concluída","Concluída",IF(AND(F2<>"",F2<TODAY()),"Atrasada","No prazo"))) -> No prazo
L3: =IF(C3="","",IF(G3="Concluída",1,N(H3))) | M3: =IF(C3="","",IF(G3="Concluída","Concluída",IF(AND(F3<>"",F3<TODAY()),"Atrasada","No prazo")))
L4: =IF(C4="","",IF(G4="Concluída",1,N(H4))) | M4: =IF(C4="","",IF(G4="Concluída","Concluída",IF(AND(F4<>"",F4<TODAY()),"Atrasada","No prazo")))
L5: =IF(C5="","",IF(G5="Concluída",1,N(H5))) | M5: =IF(C5="","",IF(G5="Concluída","Concluída",IF(AND(F5<>"",F5<TODAY()),"Atrasada","No prazo")))
L6: =IF(C6="","",IF(G6="Concluída",1,N(H6))) | M6: =IF(C6="","",IF(G6="Concluída","Concluída",IF(AND(F6<>"",F6<TODAY()),"Atrasada","No prazo")))
L7: =IF(C7="","",IF(G7="Concluída",1,N(H7))) | M7: =IF(C7="","",IF(G7="Concluída","Concluída",IF(AND(F7<>"",F7<TODAY()),"Atrasada","No prazo")))
L8: =IF(C8="","",IF(G8="Concluída",1,N(H8))) | M8: =IF(C8="","",IF(G8="Concluída","Concluída",IF(AND(F8<>"",F8<TODAY()),"Atrasada","No prazo")))
L9: =IF(C9="","",IF(G9="Concluída",1,N(H9))) | M9: =IF(C9="","",IF(G9="Concluída","Concluída",IF(AND(F9<>"",F9<TODAY()),"Atrasada","No prazo")))
L10: =IF(C10="","",IF(G10="Concluída",1,N(H10))) | M10: =IF(C10="","",IF(G10="Concluída","Concluída",IF(AND(F10<>"",F10<TODAY()),"Atrasada","No prazo")))
L11: =IF(C11="","",IF(G11="Concluída",1,N(H11))) | M11: =IF(C11="","",IF(G11="Concluída","Concluída",IF(AND(F11<>"",F11<TODAY()),"Atrasada","No prazo")))
L12: =IF(C12="","",IF(G12="Concluída",1,N(H12))) | M12: =IF(C12="","",IF(G12="Concluída","Concluída",IF(AND(F12<>"",F12<TODAY()),"Atrasada","No prazo")))
L13: =IF(C13="","",IF(G13="Concluída",1,N(H13))) | M13: =IF(C13="","",IF(G13="Concluída","Concluída",IF(AND(F13<>"",F13<TODAY()),"Atrasada","No prazo")))
L14: =IF(C14="","",IF(G14="Concluída",1,N(H14))) | M14: =IF(C14="","",IF(G14="Concluída","Concluída",IF(AND(F14<>"",F14<TODAY()),"Atrasada","No prazo")))
... L1000: =IF(C1000="","",IF(G1000="Concluída",1,N(H1000))) | M1000: =IF(C1000="","",IF(G1000="Concluída","Concluída",IF(AND(F1000<>"",F1000<TODAY()),"Atrasada","No prazo")))

Sheet fornecedor_painel
A1: Expansão por fornecedor
A2: Escolha o fornecedor na célula amarela. Os números vêm da posição mais recente em posicoes_fornecedor.
A4: Fornecedor | B4: Vonder
A5: Filial | B5: =IF($B$4="","",IFERROR(INDEX(fornecedores!$B$2:$B$200,MATCH($B$4,fornecedores!$A$2:$A$200,0))&"",""))
A6: Modelo | B6: =IF($B$4="","",IFERROR(INDEX(fornecedores!$C$2:$C$200,MATCH($B$4,fornecedores!$A$2:$A$200,0))&"",""))
A7: Posição de | B7: =IF($B$4="","",IFERROR(INDEX(fornecedores!$D$2:$D$200,MATCH($B$4,fornecedores!$A$2:$A$200,0)),""))
A8: Produtos no catálogo | B8: =IF($B$4="","",IFERROR(INDEX(fornecedores!$E$2:$E$200,MATCH($B$4,fornecedores!$A$2:$A$200,0)),""))
A9: Cadastrados no ERP | B9: =IF($B$4="","",IFERROR(INDEX(fornecedores!$F$2:$F$200,MATCH($B$4,fornecedores!$A$2:$A$200,0)),""))
A10: Disponíveis para venda | B10: =IF($B$4="","",IFERROR(INDEX(fornecedores!$G$2:$G$200,MATCH($B$4,fornecedores!$A$2:$A$200,0)),""))
A11: Faltam cadastrar | B11: =IF($B$4="","",IFERROR(INDEX(fornecedores!$H$2:$H$200,MATCH($B$4,fornecedores!$A$2:$A$200,0)),""))
A12: Cobertura de cadastro | B12: =IF($B$4="","",IFERROR(INDEX(fornecedores!$I$2:$I$200,MATCH($B$4,fornecedores!$A$2:$A$200,0)),""))
A13: Cobertura de venda | B13: =IF($B$4="","",IFERROR(INDEX(fornecedores!$J$2:$J$200,MATCH($B$4,fornecedores!$A$2:$A$200,0)),""))
A15: Sem posição registrada, os números ficam em branco: a base para essa cobertura ainda não existe.

Sheet fornecedores
A1: Fornecedor | B1: Filial | C1: Modelo | D1: Última posição | E1: Catálogo | F1: Cadastrados | G1: Disponíveis | H1: A cadastrar | I1: Cobertura de cadastro | J1: Cobertura de venda
A2: Fornecedor Exemplo | B2: Itajaí | C2: Cross-docking | D2: =IF($A2="","",IF(SUMPRODUCT(MAX((posicoes_fornecedor!$B$3:$B$1000=$A2)*posicoes_fornecedor!$A$3:$A$1000))=0,"",SUMPRODUCT(MAX((posicoes_fornecedor!$B$3:$B$1000=$A2)*posicoes_fornecedor!$A$3:$A$1000)))) | E2: =IF($D2="","",SUMIFS(posicoes_fornecedor!$C$3:$C$1000,posicoes_fornecedor!$B$3:$B$1000,$A2,posicoes_fornecedor!$A$3:$A$1000,$D2)) | F2: =IF($D2="","",SUMIFS(posicoes_fornecedor!$D$3:$D$1000,posicoes_fornecedor!$B$3:$B$1000,$A2,posicoes_fornecedor!$A$3:$A$1000,$D2)) | G2: =IF($D2="","",SUMIFS(posicoes_fornecedor!$E$3:$E$1000,posicoes_fornecedor!$B$3:$B$1000,$A2,posicoes_fornecedor!$A$3:$A$1000,$D2)) | H2: =IF($E2="","",$E2-$F2) | I2: =IF(OR($E2="",$E2=0),"",$F2/$E2) | J2: =IF(OR($E2="",$E2=0),"",$G2/$E2)
A3: Vonder | D3: =IF($A3="","",IF(SUMPRODUCT(MAX((posicoes_fornecedor!$B$3:$B$1000=$A3)*posicoes_fornecedor!$A$3:$A$1000))=0,"",SUMPRODUCT(MAX((posicoes_fornecedor!$B$3:$B$1000=$A3)*posicoes_fornecedor!$A$3:$A$1000)))) | E3: =IF($D3="","",SUMIFS(posicoes_fornecedor!$C$3:$C$1000,posicoes_fornecedor!$B$3:$B$1000,$A3,posicoes_fornecedor!$A$3:$A$1000,$D3)) | F3: =IF($D3="","",SUMIFS(posicoes_fornecedor!$D$3:$D$1000,posicoes_fornecedor!$B$3:$B$1000,$A3,posicoes_fornecedor!$A$3:$A$1000,$D3)) | G3: =IF($D3="","",SUMIFS(posicoes_fornecedor!$E$3:$E$1000,posicoes_fornecedor!$B$3:$B$1000,$A3,posicoes_fornecedor!$A$3:$A$1000,$D3)) | H3: =IF($E3="","",$E3-$F3) | I3: =IF(OR($E3="",$E3=0),"",$F3/$E3) | J3: =IF(OR($E3="",$E3=0),"",$G3/$E3)
D4: =IF($A4="","",IF(SUMPRODUCT(MAX((posicoes_fornecedor!$B$3:$B$1000=$A4)*posicoes_fornecedor!$A$3:$A$1000))=0,"",SUMPRODUCT(MAX((posicoes_fornecedor!$B$3:$B$1000=$A4)*posicoes_fornecedor!$A$3:$A$1000)))) | E4: =IF($D4="","",SUMIFS(posicoes_fornecedor!$C$3:$C$1000,posicoes_fornecedor!$B$3:$B$1000,$A4,posicoes_fornecedor!$A$3:$A$1000,$D4)) | F4: =IF($D4="","",SUMIFS(posicoes_fornecedor!$D$3:$D$1000,posicoes_fornecedor!$B$3:$B$1000,$A4,posicoes_fornecedor!$A$3:$A$1000,$D4)) | G4: =IF($D4="","",SUMIFS(posicoes_fornecedor!$E$3:$E$1000,posicoes_fornecedor!$B$3:$B$1000,$A4,posicoes_fornecedor!$A$3:$A$1000,$D4)) | H4: =IF($E4="","",$E4-$F4) | I4: =IF(OR($E4="",$E4=0),"",$F4/$E4) | J4: =IF(OR($E4="",$E4=0),"",$G4/$E4)
D5: =IF($A5="","",IF(SUMPRODUCT(MAX((posicoes_fornecedor!$B$3:$B$1000=$A5)*posicoes_fornecedor!$A$3:$A$1000))=0,"",SUMPRODUCT(MAX((posicoes_fornecedor!$B$3:$B$1000=$A5)*posicoes_fornecedor!$A$3:$A$1000)))) | E5: =IF($D5="","",SUMIFS(posicoes_fornecedor!$C$3:$C$1000,posicoes_fornecedor!$B$3:$B$1000,$A5,posicoes_fornecedor!$A$3:$A$1000,$D5)) | F5: =IF($D5="","",SUMIFS(posicoes_fornecedor!$D$3:$D$1000,posicoes_fornecedor!$B$3:$B$1000,$A5,posicoes_fornecedor!$A$3:$A$1000,$D5)) | G5: =IF($D5="","",SUMIFS(posicoes_fornecedor!$E$3:$E$1000,posicoes_fornecedor!$B$3:$B$1000,$A5,posicoes_fornecedor!$A$3:$A$1000,$D5)) | H5: =IF($E5="","",$E5-$F5) | I5: =IF(OR($E5="",$E5=0),"",$F5/$E5) | J5: =IF(OR($E5="",$E5=0),"",$G5/$E5)
D6: =IF($A6="","",IF(SUMPRODUCT(MAX((posicoes_fornecedor!$B$3:$B$1000=$A6)*posicoes_fornecedor!$A$3:$A$1000))=0,"",SUMPRODUCT(MAX((posicoes_fornecedor!$B$3:$B$1000=$A6)*posicoes_fornecedor!$A$3:$A$1000)))) | E6: =IF($D6="","",SUMIFS(posicoes_fornecedor!$C$3:$C$1000,posicoes_fornecedor!$B$3:$B$1000,$A6,posicoes_fornecedor!$A$3:$A$1000,$D6)) | F6: =IF($D6="","",SUMIFS(posicoes_fornecedor!$D$3:$D$1000,posicoes_fornecedor!$B$3:$B$1000,$A6,posicoes_fornecedor!$A$3:$A$1000,$D6)) | G6: =IF($D6="","",SUMIFS(posicoes_fornecedor!$E$3:$E$1000,posicoes_fornecedor!$B$3:$B$1000,$A6,posicoes_fornecedor!$A$3:$A$1000,$D6)) | H6: =IF($E6="","",$E6-$F6) | I6: =IF(OR($E6="",$E6=0),"",$F6/$E6) | J6: =IF(OR($E6="",$E6=0),"",$G6/$E6)
D7: =IF($A7="","",IF(SUMPRODUCT(MAX((posicoes_fornecedor!$B$3:$B$1000=$A7)*posicoes_fornecedor!$A$3:$A$1000))=0,"",SUMPRODUCT(MAX((posicoes_fornecedor!$B$3:$B$1000=$A7)*posicoes_fornecedor!$A$3:$A$1000)))) | E7: =IF($D7="","",SUMIFS(posicoes_fornecedor!$C$3:$C$1000,posicoes_fornecedor!$B$3:$B$1000,$A7,posicoes_fornecedor!$A$3:$A$1000,$D7)) | F7: =IF($D7="","",SUMIFS(posicoes_fornecedor!$D$3:$D$1000,posicoes_fornecedor!$B$3:$B$1000,$A7,posicoes_fornecedor!$A$3:$A$1000,$D7)) | G7: =IF($D7="","",SUMIFS(posicoes_fornecedor!$E$3:$E$1000,posicoes_fornecedor!$B$3:$B$1000,$A7,posicoes_fornecedor!$A$3:$A$1000,$D7)) | H7: =IF($E7="","",$E7-$F7) | I7: =IF(OR($E7="",$E7=0),"",$F7/$E7) | J7: =IF(OR($E7="",$E7=0),"",$G7/$E7)
D8: =IF($A8="","",IF(SUMPRODUCT(MAX((posicoes_fornecedor!$B$3:$B$1000=$A8)*posicoes_fornecedor!$A$3:$A$1000))=0,"",SUMPRODUCT(MAX((posicoes_fornecedor!$B$3:$B$1000=$A8)*posicoes_fornecedor!$A$3:$A$1000)))) | E8: =IF($D8="","",SUMIFS(posicoes_fornecedor!$C$3:$C$1000,posicoes_fornecedor!$B$3:$B$1000,$A8,posicoes_fornecedor!$A$3:$A$1000,$D8)) | F8: =IF($D8="","",SUMIFS(posicoes_fornecedor!$D$3:$D$1000,posicoes_fornecedor!$B$3:$B$1000,$A8,posicoes_fornecedor!$A$3:$A$1000,$D8)) | G8: =IF($D8="","",SUMIFS(posicoes_fornecedor!$E$3:$E$1000,posicoes_fornecedor!$B$3:$B$1000,$A8,posicoes_fornecedor!$A$3:$A$1000,$D8)) | H8: =IF($E8="","",$E8-$F8) | I8: =IF(OR($E8="",$E8=0),"",$F8/$E8) | J8: =IF(OR($E8="",$E8=0),"",$G8/$E8)
D9: =IF($A9="","",IF(SUMPRODUCT(MAX((posicoes_fornecedor!$B$3:$B$1000=$A9)*posicoes_fornecedor!$A$3:$A$1000))=0,"",SUMPRODUCT(MAX((posicoes_fornecedor!$B$3:$B$1000=$A9)*posicoes_fornecedor!$A$3:$A$1000)))) | E9: =IF($D9="","",SUMIFS(posicoes_fornecedor!$C$3:$C$1000,posicoes_fornecedor!$B$3:$B$1000,$A9,posicoes_fornecedor!$A$3:$A$1000,$D9)) | F9: =IF($D9="","",SUMIFS(posicoes_fornecedor!$D$3:$D$1000,posicoes_fornecedor!$B$3:$B$1000,$A9,posicoes_fornecedor!$A$3:$A$1000,$D9)) | G9: =IF($D9="","",SUMIFS(posicoes_fornecedor!$E$3:$E$1000,posicoes_fornecedor!$B$3:$B$1000,$A9,posicoes_fornecedor!$A$3:$A$1000,$D9)) | H9: =IF($E9="","",$E9-$F9) | I9: =IF(OR($E9="",$E9=0),"",$F9/$E9) | J9: =IF(OR($E9="",$E9=0),"",$G9/$E9)
D10: =IF($A10="","",IF(SUMPRODUCT(MAX((posicoes_fornecedor!$B$3:$B$1000=$A10)*posicoes_fornecedor!$A$3:$A$1000))=0,"",SUMPRODUCT(MAX((posicoes_fornecedor!$B$3:$B$1000=$A10)*posicoes_fornecedor!$A$3:$A$1000)))) | E10: =IF($D10="","",SUMIFS(posicoes_fornecedor!$C$3:$C$1000,posicoes_fornecedor!$B$3:$B$1000,$A10,posicoes_fornecedor!$A$3:$A$1000,$D10)) | F10: =IF($D10="","",SUMIFS(posicoes_fornecedor!$D$3:$D$1000,posicoes_fornecedor!$B$3:$B$1000,$A10,posicoes_fornecedor!$A$3:$A$1000,$D10)) | G10: =IF($D10="","",SUMIFS(posicoes_fornecedor!$E$3:$E$1000,posicoes_fornecedor!$B$3:$B$1000,$A10,posicoes_fornecedor!$A$3:$A$1000,$D10)) | H10: =IF($E10="","",$E10-$F10) | I10: =IF(OR($E10="",$E10=0),"",$F10/$E10) | J10: =IF(OR($E10="",$E10=0),"",$G10/$E10)
D11: =IF($A11="","",IF(SUMPRODUCT(MAX((posicoes_fornecedor!$B$3:$B$1000=$A11)*posicoes_fornecedor!$A$3:$A$1000))=0,"",SUMPRODUCT(MAX((posicoes_fornecedor!$B$3:$B$1000=$A11)*posicoes_fornecedor!$A$3:$A$1000)))) | E11: =IF($D11="","",SUMIFS(posicoes_fornecedor!$C$3:$C$1000,posicoes_fornecedor!$B$3:$B$1000,$A11,posicoes_fornecedor!$A$3:$A$1000,$D11)) | F11: =IF($D11="","",SUMIFS(posicoes_fornecedor!$D$3:$D$1000,posicoes_fornecedor!$B$3:$B$1000,$A11,posicoes_fornecedor!$A$3:$A$1000,$D11)) | G11: =IF($D11="","",SUMIFS(posicoes_fornecedor!$E$3:$E$1000,posicoes_fornecedor!$B$3:$B$1000,$A11,posicoes_fornecedor!$A$3:$A$1000,$D11)) | H11: =IF($E11="","",$E11-$F11) | I11: =IF(OR($E11="",$E11=0),"",$F11/$E11) | J11: =IF(OR($E11="",$E11=0),"",$G11/$E11)
D12: =IF($A12="","",IF(SUMPRODUCT(MAX((posicoes_fornecedor!$B$3:$B$1000=$A12)*posicoes_fornecedor!$A$3:$A$1000))=0,"",SUMPRODUCT(MAX((posicoes_fornecedor!$B$3:$B$1000=$A12)*posicoes_fornecedor!$A$3:$A$1000)))) | E12: =IF($D12="","",SUMIFS(posicoes_fornecedor!$C$3:$C$1000,posicoes_fornecedor!$B$3:$B$1000,$A12,posicoes_fornecedor!$A$3:$A$1000,$D12)) | F12: =IF($D12="","",SUMIFS(posicoes_fornecedor!$D$3:$D$1000,posicoes_fornecedor!$B$3:$B$1000,$A12,posicoes_fornecedor!$A$3:$A$1000,$D12)) | G12: =IF($D12="","",SUMIFS(posicoes_fornecedor!$E$3:$E$1000,posicoes_fornecedor!$B$3:$B$1000,$A12,posicoes_fornecedor!$A$3:$A$1000,$D12)) | H12: =IF($E12="","",$E12-$F12) | I12: =IF(OR($E12="",$E12=0),"",$F12/$E12) | J12: =IF(OR($E12="",$E12=0),"",$G12/$E12)
D13: =IF($A13="","",IF(SUMPRODUCT(MAX((posicoes_fornecedor!$B$3:$B$1000=$A13)*posicoes_fornecedor!$A$3:$A$1000))=0,"",SUMPRODUCT(MAX((posicoes_fornecedor!$B$3:$B$1000=$A13)*posicoes_fornecedor!$A$3:$A$1000)))) | E13: =IF($D13="","",SUMIFS(posicoes_fornecedor!$C$3:$C$1000,posicoes_fornecedor!$B$3:$B$1000,$A13,posicoes_fornecedor!$A$3:$A$1000,$D13)) | F13: =IF($D13="","",SUMIFS(posicoes_fornecedor!$D$3:$D$1000,posicoes_fornecedor!$B$3:$B$1000,$A13,posicoes_fornecedor!$A$3:$A$1000,$D13)) | G13: =IF($D13="","",SUMIFS(posicoes_fornecedor!$E$3:$E$1000,posicoes_fornecedor!$B$3:$B$1000,$A13,posicoes_fornecedor!$A$3:$A$1000,$D13)) | H13: =IF($E13="","",$E13-$F13) | I13: =IF(OR($E13="",$E13=0),"",$F13/$E13) | J13: =IF(OR($E13="",$E13=0),"",$G13/$E13)
D14: =IF($A14="","",IF(SUMPRODUCT(MAX((posicoes_fornecedor!$B$3:$B$1000=$A14)*posicoes_fornecedor!$A$3:$A$1000))=0,"",SUMPRODUCT(MAX((posicoes_fornecedor!$B$3:$B$1000=$A14)*posicoes_fornecedor!$A$3:$A$1000)))) | E14: =IF($D14="","",SUMIFS(posicoes_fornecedor!$C$3:$C$1000,posicoes_fornecedor!$B$3:$B$1000,$A14,posicoes_fornecedor!$A$3:$A$1000,$D14)) | F14: =IF($D14="","",SUMIFS(posicoes_fornecedor!$D$3:$D$1000,posicoes_fornecedor!$B$3:$B$1000,$A14,posicoes_fornecedor!$A$3:$A$1000,$D14)) | G14: =IF($D14="","",SUMIFS(posicoes_fornecedor!$E$3:$E$1000,posicoes_fornecedor!$B$3:$B$1000,$A14,posicoes_fornecedor!$A$3:$A$1000,$D14)) | H14: =IF($E14="","",$E14-$F14) | I14: =IF(OR($E14="",$E14=0),"",$F14/$E14) | J14: =IF(OR($E14="",$E14=0),"",$G14/$E14)
D15: =IF($A15="","",IF(SUMPRODUCT(MAX((posicoes_fornecedor!$B$3:$B$1000=$A15)*posicoes_fornecedor!$A$3:$A$1000))=0,"",SUMPRODUCT(MAX((posicoes_fornecedor!$B$3:$B$1000=$A15)*posicoes_fornecedor!$A$3:$A$1000)))) | E15: =IF($D15="","",SUMIFS(posicoes_fornecedor!$C$3:$C$1000,posicoes_fornecedor!$B$3:$B$1000,$A15,posicoes_fornecedor!$A$3:$A$1000,$D15)) | F15: =IF($D15="","",SUMIFS(posicoes_fornecedor!$D$3:$D$1000,posicoes_fornecedor!$B$3:$B$1000,$A15,posicoes_fornecedor!$A$3:$A$1000,$D15)) | G15: =IF($D15="","",SUMIFS(posicoes_fornecedor!$E$3:$E$1000,posicoes_fornecedor!$B$3:$B$1000,$A15,posicoes_fornecedor!$A$3:$A$1000,$D15)) | H15: =IF($E15="","",$E15-$F15) | I15: =IF(OR($E15="",$E15=0),"",$F15/$E15) | J15: =IF(OR($E15="",$E15=0),"",$G15/$E15)
... D200: =IF($A200="","",IF(SUMPRODUCT(MAX((posicoes_fornecedor!$B$3:$B$1000=$A200)*posicoes_fornecedor!$A$3:$A$1000))=0,"",SUMPRODUCT(MAX((posicoes_fornecedor!$B$3:$B$1000=$A200)*posicoes_fornecedor!$A$3:$A$1000)))) | E200: =IF($D200="","",SUMIFS(posicoes_fornecedor!$C$3:$C$1000,posicoes_fornecedor!$B$3:$B$1000,$A200,posicoes_fornecedor!$A$3:$A$1000,$D200)) | F200: =IF($D200="","",SUMIFS(posicoes_fornecedor!$D$3:$D$1000,posicoes_fornecedor!$B$3:$B$1000,$A200,posicoes_fornecedor!$A$3:$A$1000,$D200)) | G200: =IF($D200="","",SUMIFS(posicoes_fornecedor!$E$3:$E$1000,posicoes_fornecedor!$B$3:$B$1000,$A200,posicoes_fornecedor!$A$3:$A$1000,$D200)) | H200: =IF($E200="","",$E200-$F200) | I200: =IF(OR($E200="",$E200=0),"",$F200/$E200) | J200: =IF(OR($E200="",$E200=0),"",$G200/$E200)

Sheet posicoes_fornecedor
A1: Data da posição | B1: Fornecedor | C1: Produtos no catálogo | D1: Cadastrados no ERP | E1: Disponíveis para venda | F1: Observação
A2: 46308 | B2: Fornecedor Exemplo | C2: 1200 | D2: 800 | E2: 650 | F2: Exemplo: apague esta linha

Sheet vonder_60
A1: Data da posição | B1: Anúncios publicados | C1: Produtos no ERP | D1: Variação de publicados | E1: Observação | G1: Meta de publicados
A2: 46308 | B2: 150 | C2: 400 | E2: Exemplo: apague esta linha | G2: Prazo da meta
D3: =IF(OR(B3="",B2="",3=3),"",B3-B2) | G3: Publicados hoje | H3: =IFERROR(LOOKUP(2,1/(B3:B1000<>""),B3:B1000),"")
D4: =IF(OR(B4="",B3="",4=3),"",B4-B3) | G4: % da meta | H4: =IF(OR(H1="",H1=0,H3=""),"",H3/H1)
D5: =IF(OR(B5="",B4="",5=3),"",B5-B4) | G5: Dias até o prazo | H5: =IF(H2="","",H2-TODAY())
D6: =IF(OR(B6="",B5="",6=3),"",B6-B5)
D7: =IF(OR(B7="",B6="",7=3),"",B7-B6)
D8: =IF(OR(B8="",B7="",8=3),"",B8-B7)
D9: =IF(OR(B9="",B8="",9=3),"",B9-B8)
D10: =IF(OR(B10="",B9="",10=3),"",B10-B9)
D11: =IF(OR(B11="",B10="",11=3),"",B11-B10)
D12: =IF(OR(B12="",B11="",12=3),"",B12-B11)
D13: =IF(OR(B13="",B12="",13=3),"",B13-B12)
D14: =IF(OR(B14="",B13="",14=3),"",B14-B13)
D15: =IF(OR(B15="",B14="",15=3),"",B15-B14)
D16: =IF(OR(B16="",B15="",16=3),"",B16-B15)
D17: =IF(OR(B17="",B16="",17=3),"",B17-B16)
D18: =IF(OR(B18="",B17="",18=3),"",B18-B17)
D19: =IF(OR(B19="",B18="",19=3),"",B19-B18)
D20: =IF(OR(B20="",B19="",20=3),"",B20-B19)
D21: =IF(OR(B21="",B20="",21=3),"",B21-B20)
D22: =IF(OR(B22="",B21="",22=3),"",B22-B21)
D23: =IF(OR(B23="",B22="",23=3),"",B23-B22)
D24: =IF(OR(B24="",B23="",24=3),"",B24-B23)
D25: =IF(OR(B25="",B24="",25=3),"",B25-B24)
D26: =IF(OR(B26="",B25="",26=3),"",B26-B25)
D27: =IF(OR(B27="",B26="",27=3),"",B27-B26)
D28: =IF(OR(B28="",B27="",28=3),"",B28-B27)
D29: =IF(OR(B29="",B28="",29=3),"",B29-B28)
D30: =IF(OR(B30="",B29="",30=3),"",B30-B29)
D31: =IF(OR(B31="",B30="",31=3),"",B31-B30)
D32: =IF(OR(B32="",B31="",32=3),"",B32-B31)
D33: =IF(OR(B33="",B32="",33=3),"",B33-B32)
D34: =IF(OR(B34="",B33="",34=3),"",B34-B33)
D35: =IF(OR(B35="",B34="",35=3),"",B35-B34)
D36: =IF(OR(B36="",B35="",36=3),"",B36-B35)
D37: =IF(OR(B37="",B36="",37=3),"",B37-B36)
D38: =IF(OR(B38="",B37="",38=3),"",B38-B37)
D39: =IF(OR(B39="",B38="",39=3),"",B39-B38)
D40: =IF(OR(B40="",B39="",40=3),"",B40-B39)
...

Sheet lotes
A1: Lote | B1: Fornecedor | C1: Recebido em | D1: Início do cadastro | E1: Concluído em | F1: Cadastrados | G1: Pendentes | H1: Devolvidos | I1: Conferência | J1: Dias de execução | K1: Recebimento → início (dias) | L1: Foi devolvido?
A2: L-001 | B2: Fornecedor Exemplo | C2: 46300 | D2: 46302 | E2: 46309 | F2: 80 | G2: 5 | H2: 3 | I2: Aprovada | J2: =IF(OR(D2="",E2=""),"",E2-D2) -> 7 | K2: =IF(OR(C2="",D2=""),"",D2-C2) -> 2 | L2: =IF(A2="","",IF(OR(I2="Devolvida",N(H2)>0),"Sim","Não")) -> Sim
J3: =IF(OR(D3="",E3=""),"",E3-D3) | K3: =IF(OR(C3="",D3=""),"",D3-C3) | L3: =IF(A3="","",IF(OR(I3="Devolvida",N(H3)>0),"Sim","Não"))
J4: =IF(OR(D4="",E4=""),"",E4-D4) | K4: =IF(OR(C4="",D4=""),"",D4-C4) | L4: =IF(A4="","",IF(OR(I4="Devolvida",N(H4)>0),"Sim","Não"))
J5: =IF(OR(D5="",E5=""),"",E5-D5) | K5: =IF(OR(C5="",D5=""),"",D5-C5) | L5: =IF(A5="","",IF(OR(I5="Devolvida",N(H5)>0),"Sim","Não"))
J6: =IF(OR(D6="",E6=""),"",E6-D6) | K6: =IF(OR(C6="",D6=""),"",D6-C6) | L6: =IF(A6="","",IF(OR(I6="Devolvida",N(H6)>0),"Sim","Não"))
J7: =IF(OR(D7="",E7=""),"",E7-D7) | K7: =IF(OR(C7="",D7=""),"",D7-C7) | L7: =IF(A7="","",IF(OR(I7="Devolvida",N(H7)>0),"Sim","Não"))
J8: =IF(OR(D8="",E8=""),"",E8-D8) | K8: =IF(OR(C8="",D8=""),"",D8-C8) | L8: =IF(A8="","",IF(OR(I8="Devolvida",N(H8)>0),"Sim","Não"))
J9: =IF(OR(D9="",E9=""),"",E9-D9) | K9: =IF(OR(C9="",D9=""),"",D9-C9) | L9: =IF(A9="","",IF(OR(I9="Devolvida",N(H9)>0),"Sim","Não"))
J10: =IF(OR(D10="",E10=""),"",E10-D10) | K10: =IF(OR(C10="",D10=""),"",D10-C10) | L10: =IF(A10="","",IF(OR(I10="Devolvida",N(H10)>0),"Sim","Não"))
J11: =IF(OR(D11="",E11=""),"",E11-D11) | K11: =IF(OR(C11="",D11=""),"",D11-C11) | L11: =IF(A11="","",IF(OR(I11="Devolvida",N(H11)>0),"Sim","Não"))
J12: =IF(OR(D12="",E12=""),"",E12-D12) | K12: =IF(OR(C12="",D12=""),"",D12-C12) | L12: =IF(A12="","",IF(OR(I12="Devolvida",N(H12)>0),"Sim","Não"))
J13: =IF(OR(D13="",E13=""),"",E13-D13) | K13: =IF(OR(C13="",D13=""),"",D13-C13) | L13: =IF(A13="","",IF(OR(I13="Devolvida",N(H13)>0),"Sim","Não"))
J14: =IF(OR(D14="",E14=""),"",E14-D14) | K14: =IF(OR(C14="",D14=""),"",D14-C14) | L14: =IF(A14="","",IF(OR(I14="Devolvida",N(H14)>0),"Sim","Não"))
... J1000: =IF(OR(D1000="",E1000=""),"",E1000-D1000) | K1000: =IF(OR(C1000="",D1000=""),"",D1000-C1000) | L1000: =IF(A1000="","",IF(OR(I1000="Devolvida",N(H1000)>0),"Sim","Não"))

Sheet clickup_tarefas
A1: ID | B1: Fonte | C1: Nome | D1: Status | E1: Responsáveis | F1: Tags | G1: Prioridade | H1: Prazo | I1: Atualizada em | J1: Concluída em | K1: Lista | L1: Filial | M1: Link | N1: Coletada em
A2: wdrhz35uct | B2: anuncios | C2: Produtos Multilaser | D2: precificação | E2: Polielly Morato | I2: 46308.693 | K2: Anúncios | M2: https://app.clickup.com/t/wdrhz35uct | N2: 46308.726
A3: wdrhz351vm | B3: anuncios | C3: Novos Produtos Britânia/Philco | D3: precificação | E3: Jean Lins, João Vitor Bernardeli, Heitor Vecchia, Marcos Luciano Domus, João Vithor Farias, Eduardo Felipe | F3: aguardando informações | G3: normal | I3: 46308.668 | K3: Anúncios | M3: https://app.clickup.com/t/wdrhz351vm | N3: 46308.726
A4: wdrhz368k8 | B4: anuncios | C4: Novos Produtos Britânia/Philco | D4: precificação | E4: João Vithor Farias, João Vitor Bernardeli, Jean Lins, Eduardo Felipe, Marcos Luciano Domus | I4: 46308.646 | K4: Anúncios | M4: https://app.clickup.com/t/wdrhz368k8 | N4: 46308.726
A5: wdrhz36e2w | B5: anuncios | C5: Novo Kit Ortobom | D5: concluído | E5: Jean Lins, Vitória Nascimento, Mairon Henrique | I5: 46308.626 | J5: 46308.626 | K5: Anúncios | M5: https://app.clickup.com/t/wdrhz36e2w | N5: 46308.726
A6: wdrhz36kvg | B6: anuncios | C6: SKUS VONDER VERTICALIZADOS SEM ANUNCIOS | D6: solicitações | E6: Jean Lins, Eduardo Felipe, Heitor Vecchia | I6: 46308.37 | K6: Anúncios | M6: https://app.clickup.com/t/wdrhz36kvg | N6: 46308.726
A7: wdrhz36p5x | B7: anuncios | C7: Trocar tags de verticalizado para cross - compras | D7: solicitações | E7: Polielly Morato | H7: 46300 | I7: 46304.715 | K7: Anúncios | M7: https://app.clickup.com/t/wdrhz36p5x | N7: 46308.726
A8: wdrhz35udj | B8: anuncios | C8: Correção descrição Morsa/Sparta | D8: concluído | E8: Polielly Morato | I8: 46304.713 | J8: 46304.713 | K8: Anúncios | M8: https://app.clickup.com/t/wdrhz35udj | N8: 46308.726
A9: wdrhz35ue3 | B9: anuncios | C9: Erro Soprador Kala Ean - Victor Recebimento | D9: concluído | E9: Polielly Morato | I9: 46304.592 | J9: 46304.592 | K9: Anúncios | M9: https://app.clickup.com/t/wdrhz35ue3 | N9: 46308.726
A10: wdrhz35ucp | B10: anuncios | C10: Produtos Soprano | D10: fotos | E10: Polielly Morato | I10: 46304.518 | K10: Anúncios | M10: https://app.clickup.com/t/wdrhz35ucp | N10: 46308.726
A11: wdrhz355v2 | B11: anuncios | C11: Cadastro WAP | D11: concluído | E11: Polielly Morato | G11: urgent | I11: 46304.515 | J11: 46304.515 | K11: Anúncios | M11: https://app.clickup.com/t/wdrhz355v2 | N11: 46308.726
A12: wdrhz35ucn | B12: anuncios | C12: Produtos Gama | D12: concluído | E12: Polielly Morato, Marcos Luciano Domus, Eduardo Felipe | G12: urgent | I12: 46304.515 | J12: 46304.515 | K12: Anúncios | M12: https://app.clickup.com/t/wdrhz35ucn | N12: 46308.726
A13: wdrhz344tv | B13: anuncios | C13: Maral Brinquedos | D13: concluído | E13: João Vitor Bernardeli, Marcos Luciano Domus, Heitor Vecchia, Eduardo Felipe | I13: 46303.807 | J13: 46303.807 | K13: Anúncios | M13: https://app.clickup.com/t/wdrhz344tv | N13: 46308.726
A14: wdrhz2xdp5 | B14: anuncios | C14: Novos produtos britania/philco | D14: concluído | E14: Jean Lins, João Vitor Bernardeli, Heitor Vecchia, Marcos Luciano Domus, João Vithor Farias, Polielly Morato, Eduardo Felipe | F14: aguardando informações, em andamento | I14: 46303.8 | J14: 46303.8 | K14: Anúncios | M14: https://app.clickup.com/t/wdrhz2xdp5 | N14: 46308.726
A15: wdrhz2vj23 | B15: anuncios | C15: Schulz | D15: concluído | E15: Pedro Sitta, Polielly Morato, Heitor Vecchia, João Vitor Bernardeli, Marcos Luciano Domus, João Vithor Farias | F15: aguardando informações, em andamento | G15: high | I15: 46303.8 | J15: 46303.8 | K15: Anúncios | M15: https://app.clickup.com/t/wdrhz2vj23 | N15: 46308.726
A16: wdrhz2v85f | B16: anuncios | C16: Kawashima | D16: concluído | E16: Polielly Morato, Pedro Sitta, João Vithor Farias, Marcos Luciano Domus, João Vitor Bernardeli, Jean Lins | F16: aguardando informações, em andamento | I16: 46303.8 | J16: 46303.8 | K16: Anúncios | M16: https://app.clickup.com/t/wdrhz2v85f | N16: 46308.726
A17: wdrhz2q4be | B17: anuncios | C17: Novos Produtos Wap | D17: concluído | E17: Polielly Morato, Pedro Sitta, Marcos Luciano Domus, João Vithor Farias, João Vitor Bernardeli, Heitor Vecchia | F17: aguardando informações, em andamento | I17: 46303.799 | J17: 46303.799 | K17: Anúncios | M17: https://app.clickup.com/t/wdrhz2q4be | N17: 46308.726
A18: wdrhz36fqk | B18: anuncios | C18: TV Philco | D18: concluído | E18: João Vitor Bernardeli, Marcos Luciano Domus, João Vithor Farias, Eduardo Felipe, Jean Lins | I18: 46303.798 | J18: 46303.798 | K18: Anúncios | M18: https://app.clickup.com/t/wdrhz36fqk | N18: 46308.726
A19: wdrhz35ue2 | B19: anuncios | C19: Cadastro de um produto Garthen - Matheus/Devolução | D19: precificação | E19: Polielly Morato, Marcos Luciano Domus, Eduardo Felipe | I19: 46303.798 | K19: Anúncios | M19: https://app.clickup.com/t/wdrhz35ue2 | N19: 46308.726
A20: wdrhz36hfg | B20: anuncios | C20: Produto Shopee | D20: concluído | E20: Eduardo Felipe, Jean Lins | I20: 46303.79 | J20: 46303.79 | K20: Anúncios | M20: https://app.clickup.com/t/wdrhz36hfg | N20: 46308.726
A21: wdrhz36d7q | B21: anuncios | C21: Colchões banidos | D21: concluído | E21: Polielly Morato | I21: 46303.786 | J21: 46303.786 | K21: Anúncios | M21: https://app.clickup.com/t/wdrhz36d7q | N21: 46308.726
A22: wdrhz36e5j | B22: anuncios | C22: Produto Ventisol | D22: precificação | E22: Eduardo Felipe, Marcos Luciano Domus, Polielly Morato | I22: 46303.764 | K22: Anúncios | M22: https://app.clickup.com/t/wdrhz36e5j | N22: 46308.726
A23: wdrhz3673f | B23: anuncios | C23: Criar Macaco Hidráulico por Toneladas e Fornecedor | D23: solicitações | E23: Jean Lins | G23: normal | I23: 46303.751 | K23: Anúncios | M23: https://app.clickup.com/t/wdrhz3673f | N23: 46308.726
A24: wdrhz34tr7 | B24: anuncios | C24: Novo SKU Wanke | D24: concluído | E24: Heitor Vecchia, Marcos Luciano Domus, João Vitor Bernardeli, João Vithor Farias, Eduardo Felipe | F24: aguardando informações | G24: high | I24: 46303.433 | J24: 46303.433 | K24: Anúncios | M24: https://app.clickup.com/t/wdrhz34tr7 | N24: 46308.726
A25: wdrhz3149f | B25: anuncios | C25: Novos Produtos Electrolux | D25: concluído | E25: Heitor Vecchia, João Vitor Bernardeli, Jean Lins, Marcos Luciano Domus, João Vithor Farias | F25: aguardando informações | I25: 46303.402 | J25: 46303.402 | K25: Anúncios | M25: https://app.clickup.com/t/wdrhz3149f | N25: 46308.726
A26: wdrhz3654t | B26: anuncios | C26: Novos Produtos Taiff | D26: concluído | E26: Eduardo Felipe, Jean Lins, João Vitor Bernardeli, Marcos Luciano Domus, João Vithor Farias | I26: 46303.364 | J26: 46303.363 | K26: Anúncios | M26: https://app.clickup.com/t/wdrhz3654t | N26: 46308.726
A27: wdrhz35ue4 | B27: anuncios | C27: Revisão Aramoveis Produtos Excluidos - Compras | D27: concluído | E27: Polielly Morato | I27: 46302.616 | J27: 46302.616 | K27: Anúncios | M27: https://app.clickup.com/t/wdrhz35ue4 | N27: 46308.726
A28: wdrhz35udy | B28: anuncios | C28: Produtos Vonder - Feira Gabriel/Gustavo | D28: concluído | E28: Polielly Morato | I28: 46302.476 | J28: 46302.476 | K28: Anúncios | M28: https://app.clickup.com/t/wdrhz35udy | N28: 46308.726
A29: 86ab982vh | B29: anuncios | C29: Meli | D29: concluído | E29: Letícia Sakashita | I29: 46301.664 | J29: 45896.619 | K29: Anúncios | M29: https://app.clickup.com/t/86ab982vh | N29: 46308.726
A30: wdrhz35wg0 | B30: anuncios | C30: PRODUTOS NOVOS WAP | D30: precificação | E30: Polielly Morato, João Vithor Farias | G30: urgent | I30: 46301.502 | K30: Anúncios | M30: https://app.clickup.com/t/wdrhz35wg0 | N30: 46308.726
A31: wdrhz2xv14 | B31: anuncios | C31: Novos Produtos Zagonel | D31: concluído | E31: Polielly Morato, Jean Lins, João Vitor Bernardeli, Marcos Luciano Domus, João Vithor Farias, Heitor Vecchia, Pedro Sitta | F31: aguardando informações, em andamento | I31: 46301.483 | J31: 46301.483 | K31: Anúncios | M31: https://app.clickup.com/t/wdrhz2xv14 | N31: 46308.726
A32: wdrhz3468p | B32: anuncios | C32: Novos Ares Condicionados Kian | D32: precificação | E32: Heitor Vecchia, João Vitor Bernardeli, Marcos Luciano Domus, João Vithor Farias, Jean Lins | I32: 46301.408 | K32: Anúncios | M32: https://app.clickup.com/t/wdrhz3468p | N32: 46308.726
A33: wdrhz360fb | B33: anuncios | C33: Kits Compressor Schulz (Shopee) | D33: concluído | E33: Eduardo Felipe, Jean Lins | G33: normal | I33: 46301.389 | J33: 46301.388 | K33: Anúncios | M33: https://app.clickup.com/t/wdrhz360fb | N33: 46308.726
A34: wdrhz35e8n | B34: anuncios | C34: Novos Produtos Caemmun | D34: subindo anúncios | E34: Mairon Henrique, Jean Lins, Vitória Nascimento | F34: londrina | I34: 46300.779 | K34: Anúncios | L34: Londrina | M34: https://app.clickup.com/t/wdrhz35e8n | N34: 46308.726
A35: wdrhz35e2p | B35: anuncios | C35: Novos Produtos HB Móveis | D35: concluído | E35: Vitória Nascimento, Mairon Henrique, Jean Lins | F35: londrina | I35: 46300.716 | J35: 46300.716 | K35: Anúncios | L35: Londrina | M35: https://app.clickup.com/t/wdrhz35e2p | N35: 46308.726
A36: wdrhz35e44 | B36: anuncios | C36: Novos Produtos Fibrasca | D36: concluído | E36: Mairon Henrique, Jean Lins, Vitória Nascimento | F36: londrina | I36: 46300.671 | J36: 46300.671 | K36: Anúncios | L36: Londrina | M36: https://app.clickup.com/t/wdrhz35e44 | N36: 46308.726
A37: wdrhz33n6v | B37: anuncios | C37: KIT Pistola + Compressor MeLi | D37: concluído | E37: Jean Lins, Marcos Luciano Domus | F37: itajai, pendente | G37: high | I37: 46297.642 | J37: 46297.636 | K37: Anúncios | L37: Itajaí | M37: https://app.clickup.com/t/wdrhz33n6v | N37: 46308.726
A38: wdrhz35wuw | B38: anuncios | C38: Compressor Verticalizado Vonder | D38: concluído | E38: Jean Lins, Eduardo Felipe, Marcos Luciano Domus, João Vithor Farias | G38: urgent | I38: 46297.547 | J38: 46297.492 | K38: Anúncios | M38: https://app.clickup.com/t/wdrhz35wuw | N38: 46308.726
A39: wdrhz34xk3 | B39: anuncios | C39: Revisar descrições Londrina | D39: solicitações | E39: Polielly Morato, Jaqueline Souza | F39: em andamento, londrina | G39: high | I39: 46297.493 | K39: Anúncios | L39: Londrina | M39: https://app.clickup.com/t/wdrhz34xk3 | N39: 46308.726
A40: wdrhz35e4v | B40: anuncios | C40: Novos Produtos Ortobom | D40: concluído | E40: Jean Lins, Mairon Henrique, Vitória Nascimento | F40: londrina | I40: 46297.384 | J40: 46297.384 | K40: Anúncios | L40: Londrina | M40: https://app.clickup.com/t/wdrhz35e4v | N40: 46308.726
...

Sheet clickup_historico
A1: Data da coleta | B1: ID da tarefa | C1: Fonte | D1: Status anterior | E1: Status novo
A2: 46309.292 | B2: wdrhz35uct | C2: anuncios | D2: precificação | E2: subindo anúncios
